Workbook

Sheet Dashboard
A1: GRAPHIC DESIGN STUDIO MANAGEMENT DASHBOARD
A2: KPI Metric | B2: Value | C2: Status Summary
A3: Total Portfolio Budget | B3: =SUM(Dashboard!B2:B51) -> 0 | C3: Briefing | D3: =COUNTIF('Project Pipeline'!H2:H51, "Briefing") -> 10
A4: Total Amount Collected | B4: ='Financial Tracking'!D53 -> 0 | C4: In Progress | D4: =COUNTIF('Project Pipeline'!H2:H51, "In Progress") -> 10
A5: Total Outstanding Balance | B5: =SUM(Dashboard!E2:E51) -> 0 | C5: Review | D5: =COUNTIF('Project Pipeline'!H2:H51, "Review") -> 10
A6: Total Projects Tracked | B6: =COUNTA('Project Pipeline'!A2:A51) -> 50 | C6: Approved | D6: =COUNTIF('Project Pipeline'!H2:H51, "Approved") -> 10
C7: On Hold | D7: =COUNTIF('Project Pipeline'!H2:H51, "On Hold") -> 10

Sheet Client Database
A1: Client ID | B1: Client Name | C1: Company | D1: Contact Email | E1: Status | F1: Total Projects | G1: Lifetime Revenue
A2: DS-CLN-001 | B2: Client Name 1 | C2: Design Labs LLC 1 | D2: contact@enterprise1.com | E2: Active | F2: =COUNTIF('Project Pipeline'!C2:C51, "DS-CLN-001") -> 5 | G2: =SUMIF('Project Pipeline'!C2:C51, "DS-CLN-001", 'Financial Tracking'!B2:B51) -> 22500
A3: DS-CLN-002 | B3: Client Name 2 | C3: Creative Enterprise 2 | D3: contact@enterprise2.com | E3: Active | F3: =COUNTIF('Project Pipeline'!C2:C51, "DS-CLN-002") -> 5 | G3: =SUMIF('Project Pipeline'!C2:C51, "DS-CLN-002", 'Financial Tracking'!B2:B51) -> 18000
A4: DS-CLN-003 | B4: Client Name 3 | C4: Design Labs LLC 3 | D4: contact@enterprise3.com | E4: Active | F4: =COUNTIF('Project Pipeline'!C2:C51, "DS-CLN-003") -> 5 | G4: =SUMIF('Project Pipeline'!C2:C51, "DS-CLN-003", 'Financial Tracking'!B2:B51) -> 18500
A5: DS-CLN-004 | B5: Client Name 4 | C5: Creative Enterprise 4 | D5: contact@enterprise4.com | E5: Active | F5: =COUNTIF('Project Pipeline'!C2:C51, "DS-CLN-004") -> 5 | G5: =SUMIF('Project Pipeline'!C2:C51, "DS-CLN-004", 'Financial Tracking'!B2:B51) -> 19000
A6: DS-CLN-005 | B6: Client Name 5 | C6: Design Labs LLC 5 | D6: contact@enterprise5.com | E6: Active | F6: =COUNTIF('Project Pipeline'!C2:C51, "DS-CLN-005") -> 5 | G6: =SUMIF('Project Pipeline'!C2:C51, "DS-CLN-005", 'Financial Tracking'!B2:B51) -> 19500
A7: DS-CLN-006 | B7: Client Name 6 | C7: Creative Enterprise 6 | D7: contact@enterprise6.com | E7: Active | F7: =COUNTIF('Project Pipeline'!C2:C51, "DS-CLN-006") -> 5 | G7: =SUMIF('Project Pipeline'!C2:C51, "DS-CLN-006", 'Financial Tracking'!B2:B51) -> 20000
A8: DS-CLN-007 | B8: Client Name 7 | C8: Design Labs LLC 7 | D8: contact@enterprise7.com | E8: Inactive | F8: =COUNTIF('Project Pipeline'!C2:C51, "DS-CLN-007") -> 5 | G8: =SUMIF('Project Pipeline'!C2:C51, "DS-CLN-007", 'Financial Tracking'!B2:B51) -> 20500
A9: DS-CLN-008 | B9: Client Name 8 | C9: Creative Enterprise 8 | D9: contact@enterprise8.com | E9: Active | F9: =COUNTIF('Project Pipeline'!C2:C51, "DS-CLN-008") -> 5 | G9: =SUMIF('Project Pipeline'!C2:C51, "DS-CLN-008", 'Financial Tracking'!B2:B51) -> 21000
A10: DS-CLN-009 | B10: Client Name 9 | C10: Design Labs LLC 9 | D10: contact@enterprise9.com | E10: Active | F10: =COUNTIF('Project Pipeline'!C2:C51, "DS-CLN-009") -> 5 | G10: =SUMIF('Project Pipeline'!C2:C51, "DS-CLN-009", 'Financial Tracking'!B2:B51) -> 21500
A11: DS-CLN-010 | B11: Client Name 10 | C11: Creative Enterprise 10 | D11: contact@enterprise10.com | E11: Active | F11: =COUNTIF('Project Pipeline'!C2:C51, "DS-CLN-010") -> 5 | G11: =SUMIF('Project Pipeline'!C2:C51, "DS-CLN-010", 'Financial Tracking'!B2:B51) -> 22000
A12: DS-CLN-011 | B12: Client Name 11 | C12: Design Labs LLC 11 | D12: contact@enterprise11.com | E12: Active | F12: =COUNTIF('Project Pipeline'!C2:C51, "DS-CLN-011") -> 0 | G12: =SUMIF('Project Pipeline'!C2:C51, "DS-CLN-011", 'Financial Tracking'!B2:B51) -> 0
A13: DS-CLN-012 | B13: Client Name 12 | C13: Creative Enterprise 12 | D13: contact@enterprise12.com | E13: Active | F13: =COUNTIF('Project Pipeline'!C2:C51, "DS-CLN-012") -> 0 | G13: =SUMIF('Project Pipeline'!C2:C51, "DS-CLN-012", 'Financial Tracking'!B2:B51) -> 0
A14: DS-CLN-013 | B14: Client Name 13 | C14: Design Labs LLC 13 | D14: contact@enterprise13.com | E14: Active | F14: =COUNTIF('Project Pipeline'!C2:C51, "DS-CLN-013") -> 0 | G14: =SUMIF('Project Pipeline'!C2:C51, "DS-CLN-013", 'Financial Tracking'!B2:B51) -> 0
A15: DS-CLN-014 | B15: Client Name 14 | C15: Creative Enterprise 14 | D15: contact@enterprise14.com | E15: Inactive | F15: =COUNTIF('Project Pipeline'!C2:C51, "DS-CLN-014") -> 0 | G15: =SUMIF('Project Pipeline'!C2:C51, "DS-CLN-014", 'Financial Tracking'!B2:B51) -> 0
A16: DS-CLN-015 | B16: Client Name 15 | C16: Design Labs LLC 15 | D16: contact@enterprise15.com | E16: Active | F16: =COUNTIF('Project Pipeline'!C2:C51, "DS-CLN-015") -> 0 | G16: =SUMIF('Project Pipeline'!C2:C51, "DS-CLN-015", 'Financial Tracking'!B2:B51) -> 0
A17: DS-CLN-016 | B17: Client Name 16 | C17: Creative Enterprise 16 | D17: contact@enterprise16.com | E17: Active | F17: =COUNTIF('Project Pipeline'!C2:C51, "DS-CLN-016") -> 0 | G17: =SUMIF('Project Pipeline'!C2:C51, "DS-CLN-016", 'Financial Tracking'!B2:B51) -> 0
A18: DS-CLN-017 | B18: Client Name 17 | C18: Design Labs LLC 17 | D18: contact@enterprise17.com | E18: Active | F18: =COUNTIF('Project Pipeline'!C2:C51, "DS-CLN-017") -> 0 | G18: =SUMIF('Project Pipeline'!C2:C51, "DS-CLN-017", 'Financial Tracking'!B2:B51) -> 0
A19: DS-CLN-018 | B19: Client Name 18 | C19: Creative Enterprise 18 | D19: contact@enterprise18.com | E19: Active | F19: =COUNTIF('Project Pipeline'!C2:C51, "DS-CLN-018") -> 0 | G19: =SUMIF('Project Pipeline'!C2:C51, "DS-CLN-018", 'Financial Tracking'!B2:B51) -> 0
A20: DS-CLN-019 | B20: Client Name 19 | C20: Design Labs LLC 19 | D20: contact@enterprise19.com | E20: Active | F20: =COUNTIF('Project Pipeline'!C2:C51, "DS-CLN-019") -> 0 | G20: =SUMIF('Project Pipeline'!C2:C51, "DS-CLN-019", 'Financial Tracking'!B2:B51) -> 0
A21: DS-CLN-020 | B21: Client Name 20 | C21: Creative Enterprise 20 | D21: contact@enterprise20.com | E21: Active | F21: =COUNTIF('Project Pipeline'!C2:C51, "DS-CLN-020") -> 0 | G21: =SUMIF('Project Pipeline'!C2:C51, "DS-CLN-020", 'Financial Tracking'!B2:B51) -> 0
A22: DS-CLN-021 | B22: Client Name 21 | C22: Design Labs LLC 21 | D22: contact@enterprise21.com | E22: Inactive | F22: =COUNTIF('Project Pipeline'!C2:C51, "DS-CLN-021") -> 0 | G22: =SUMIF('Project Pipeline'!C2:C51, "DS-CLN-021", 'Financial Tracking'!B2:B51) -> 0
A23: DS-CLN-022 | B23: Client Name 22 | C23: Creative Enterprise 22 | D23: contact@enterprise22.com | E23: Active | F23: =COUNTIF('Project Pipeline'!C2:C51, "DS-CLN-022") -> 0 | G23: =SUMIF('Project Pipeline'!C2:C51, "DS-CLN-022", 'Financial Tracking'!B2:B51) -> 0
A24: DS-CLN-023 | B24: Client Name 23 | C24: Design Labs LLC 23 | D24: contact@enterprise23.com | E24: Active | F24: =COUNTIF('Project Pipeline'!C2:C51, "DS-CLN-023") -> 0 | G24: =SUMIF('Project Pipeline'!C2:C51, "DS-CLN-023", 'Financial Tracking'!B2:B51) -> 0
A25: DS-CLN-024 | B25: Client Name 24 | C25: Creative Enterprise 24 | D25: contact@enterprise24.com | E25: Active | F25: =COUNTIF('Project Pipeline'!C2:C51, "DS-CLN-024") -> 0 | G25: =SUMIF('Project Pipeline'!C2:C51, "DS-CLN-024", 'Financial Tracking'!B2:B51) -> 0
A26: DS-CLN-025 | B26: Client Name 25 | C26: Design Labs LLC 25 | D26: contact@enterprise25.com | E26: Active | F26: =COUNTIF('Project Pipeline'!C2:C51, "DS-CLN-025") -> 0 | G26: =SUMIF('Project Pipeline'!C2:C51, "DS-CLN-025", 'Financial Tracking'!B2:B51) -> 0
A27: DS-CLN-026 | B27: Client Name 26 | C27: Creative Enterprise 26 | D27: contact@enterprise26.com | E27: Active | F27: =COUNTIF('Project Pipeline'!C2:C51, "DS-CLN-026") -> 0 | G27: =SUMIF('Project Pipeline'!C2:C51, "DS-CLN-026", 'Financial Tracking'!B2:B51) -> 0
A28: DS-CLN-027 | B28: Client Name 27 | C28: Design Labs LLC 27 | D28: contact@enterprise27.com | E28: Active | F28: =COUNTIF('Project Pipeline'!C2:C51, "DS-CLN-027") -> 0 | G28: =SUMIF('Project Pipeline'!C2:C51, "DS-CLN-027", 'Financial Tracking'!B2:B51) -> 0
A29: DS-CLN-028 | B29: Client Name 28 | C29: Creative Enterprise 28 | D29: contact@enterprise28.com | E29: Inactive | F29: =COUNTIF('Project Pipeline'!C2:C51, "DS-CLN-028") -> 0 | G29: =SUMIF('Project Pipeline'!C2:C51, "DS-CLN-028", 'Financial Tracking'!B2:B51) -> 0
A30: DS-CLN-029 | B30: Client Name 29 | C30: Design Labs LLC 29 | D30: contact@enterprise29.com | E30: Active | F30: =COUNTIF('Project Pipeline'!C2:C51, "DS-CLN-029") -> 0 | G30: =SUMIF('Project Pipeline'!C2:C51, "DS-CLN-029", 'Financial Tracking'!B2:B51) -> 0
A31: DS-CLN-030 | B31: Client Name 30 | C31: Creative Enterprise 30 | D31: contact@enterprise30.com | E31: Active | F31: =COUNTIF('Project Pipeline'!C2:C51, "DS-CLN-030") -> 0 | G31: =SUMIF('Project Pipeline'!C2:C51, "DS-CLN-030", 'Financial Tracking'!B2:B51) -> 0
A32: DS-CLN-031 | B32: Client Name 31 | C32: Design Labs LLC 31 | D32: contact@enterprise31.com | E32: Active | F32: =COUNTIF('Project Pipeline'!C2:C51, "DS-CLN-031") -> 0 | G32: =SUMIF('Project Pipeline'!C2:C51, "DS-CLN-031", 'Financial Tracking'!B2:B51) -> 0
A33: DS-CLN-032 | B33: Client Name 32 | C33: Creative Enterprise 32 | D33: contact@enterprise32.com | E33: Active | F33: =COUNTIF('Project Pipeline'!C2:C51, "DS-CLN-032") -> 0 | G33: =SUMIF('Project Pipeline'!C2:C51, "DS-CLN-032", 'Financial Tracking'!B2:B51) -> 0
A34: DS-CLN-033 | B34: Client Name 33 | C34: Design Labs LLC 33 | D34: contact@enterprise33.com | E34: Active | F34: =COUNTIF('Project Pipeline'!C2:C51, "DS-CLN-033") -> 0 | G34: =SUMIF('Project Pipeline'!C2:C51, "DS-CLN-033", 'Financial Tracking'!B2:B51) -> 0
A35: DS-CLN-034 | B35: Client Name 34 | C35: Creative Enterprise 34 | D35: contact@enterprise34.com | E35: Active | F35: =COUNTIF('Project Pipeline'!C2:C51, "DS-CLN-034") -> 0 | G35: =SUMIF('Project Pipeline'!C2:C51, "DS-CLN-034", 'Financial Tracking'!B2:B51) -> 0
A36: DS-CLN-035 | B36: Client Name 35 | C36: Design Labs LLC 35 | D36: contact@enterprise35.com | E36: Inactive | F36: =COUNTIF('Project Pipeline'!C2:C51, "DS-CLN-035") -> 0 | G36: =SUMIF('Project Pipeline'!C2:C51, "DS-CLN-035", 'Financial Tracking'!B2:B51) -> 0
A37: DS-CLN-036 | B37: Client Name 36 | C37: Creative Enterprise 36 | D37: contact@enterprise36.com | E37: Active | F37: =COUNTIF('Project Pipeline'!C2:C51, "DS-CLN-036") -> 0 | G37: =SUMIF('Project Pipeline'!C2:C51, "DS-CLN-036", 'Financial Tracking'!B2:B51) -> 0
A38: DS-CLN-037 | B38: Client Name 37 | C38: Design Labs LLC 37 | D38: contact@enterprise37.com | E38: Active | F38: =COUNTIF('Project Pipeline'!C2:C51, "DS-CLN-037") -> 0 | G38: =SUMIF('Project Pipeline'!C2:C51, "DS-CLN-037", 'Financial Tracking'!B2:B51) -> 0
A39: DS-CLN-038 | B39: Client Name 38 | C39: Creative Enterprise 38 | D39: contact@enterprise38.com | E39: Active | F39: =COUNTIF('Project Pipeline'!C2:C51, "DS-CLN-038") -> 0 | G39: =SUMIF('Project Pipeline'!C2:C51, "DS-CLN-038", 'Financial Tracking'!B2:B51) -> 0
A40: DS-CLN-039 | B40: Client Name 39 | C40: Design Labs LLC 39 | D40: contact@enterprise39.com | E40: Active | F40: =COUNTIF('Project Pipeline'!C2:C51, "DS-CLN-039") -> 0 | G40: =SUMIF('Project Pipeline'!C2:C51, "DS-CLN-039", 'Financial Tracking'!B2:B51) -> 0
...

Sheet Project Pipeline
A1: Project ID | B1: Project Name | C1: Client ID | D1: Project Type | E1: Assigned Designer | F1: Start Date | G1: Due Date | H1: Status | I1: Progress (%) | J1: Overdue Status
A2: DS-PRJ-001 | B2: Campaign Project 1 | C2: DS-CLN-002 | D2: Web Design | E2: Muhammad Jawad | F2: 46144 | G2: 46158 | H2: In Progress | I2: 0.5 | J2: =IF(H2="Approved", "Completed", IF(G2<TODAY(), "OVERDUE", "On Track")) -> OVERDUE
A3: DS-PRJ-002 | B3: Campaign Project 2 | C3: DS-CLN-003 | D3: UI/UX | E3: Sarah Khan | F3: 46145 | G3: 46159 | H3: Review | I3: 0.5 | J3: =IF(H3="Approved", "Completed", IF(G3<TODAY(), "OVERDUE", "On Track")) -> OVERDUE
A4: DS-PRJ-003 | B4: Campaign Project 3 | C4: DS-CLN-004 | D4: Social Media | E4: Zain Ahmed | F4: 46146 | G4: 46160 | H4: Approved | I4: 1 | J4: =IF(H4="Approved", "Completed", IF(G4<TODAY(), "OVERDUE", "On Track")) -> Completed
A5: DS-PRJ-004 | B5: Campaign Project 4 | C5: DS-CLN-005 | D5: Packaging | E5: Amna Javed | F5: 46147 | G5: 46161 | H5: On Hold | I5: 0.5 | J5: =IF(H5="Approved", "Completed", IF(G5<TODAY(), "OVERDUE", "On Track")) -> OVERDUE
A6: DS-PRJ-005 | B6: Campaign Project 5 | C6: DS-CLN-006 | D6: Branding | E6: Muhammad Jawad | F6: 46148 | G6: 46162 | H6: Briefing | I6: 0 | J6: =IF(H6="Approved", "Completed", IF(G6<TODAY(), "OVERDUE", "On Track")) -> OVERDUE
A7: DS-PRJ-006 | B7: Campaign Project 6 | C7: DS-CLN-007 | D7: Web Design | E7: Sarah Khan | F7: 46149 | G7: 46163 | H7: In Progress | I7: 0.5 | J7: =IF(H7="Approved", "Completed", IF(G7<TODAY(), "OVERDUE", "On Track")) -> OVERDUE
A8: DS-PRJ-007 | B8: Campaign Project 7 | C8: DS-CLN-008 | D8: UI/UX | E8: Zain Ahmed | F8: 46150 | G8: 46164 | H8: Review | I8: 0.5 | J8: =IF(H8="Approved", "Completed", IF(G8<TODAY(), "OVERDUE", "On Track")) -> OVERDUE
A9: DS-PRJ-008 | B9: Campaign Project 8 | C9: DS-CLN-009 | D9: Social Media | E9: Amna Javed | F9: 46151 | G9: 46165 | H9: Approved | I9: 1 | J9: =IF(H9="Approved", "Completed", IF(G9<TODAY(), "OVERDUE", "On Track")) -> Completed
A10: DS-PRJ-009 | B10: Campaign Project 9 | C10: DS-CLN-010 | D10: Packaging | E10: Muhammad Jawad | F10: 46152 | G10: 46166 | H10: On Hold | I10: 0.5 | J10: =IF(H10="Approved", "Completed", IF(G10<TODAY(), "OVERDUE", "On Track")) -> OVERDUE
A11: DS-PRJ-010 | B11: Campaign Project 10 | C11: DS-CLN-001 | D11: Branding | E11: Sarah Khan | F11: 46153 | G11: 46167 | H11: Briefing | I11: 0 | J11: =IF(H11="Approved", "Completed", IF(G11<TODAY(), "OVERDUE", "On Track")) -> OVERDUE
A12: DS-PRJ-011 | B12: Campaign Project 11 | C12: DS-CLN-002 | D12: Web Design | E12: Zain Ahmed | F12: 46154 | G12: 46168 | H12: In Progress | I12: 0.5 | J12: =IF(H12="Approved", "Completed", IF(G12<TODAY(), "OVERDUE", "On Track")) -> OVERDUE
A13: DS-PRJ-012 | B13: Campaign Project 12 | C13: DS-CLN-003 | D13: UI/UX | E13: Amna Javed | F13: 46155 | G13: 46169 | H13: Review | I13: 0.5 | J13: =IF(H13="Approved", "Completed", IF(G13<TODAY(), "OVERDUE", "On Track")) -> OVERDUE
... A51: DS-PRJ-050 | B51: Campaign Project 50 | C51: DS-CLN-001 | D51: Branding | E51: Sarah Khan | F51: 46193 | G51: 46207 | H51: Briefing | I51: 0 | J51: =IF(H51="Approved", "Completed", IF(G51<TODAY(), "OVERDUE", "On Track")) -> On Track

Sheet Team Allocation
A1: Designer Name | B1: Role | C1: Active Projects | D1: Weekly Capacity (Hrs) | E1: Allocated Hrs | F1: Utilization Rate (%)
A2: Amna Javed | B2: Senior Designer | C2: =COUNTIFS('Project Pipeline'!E$2:E$51, A2,'Project Pipeline'!H$2:H$51, "<>Approved") -> 9 | D2: 40 | E2: 10 | F2: =E2/D2 -> 0.25
A3: Muhammad Jawad | B3: UI/UX Specialist | C3: =COUNTIFS('Project Pipeline'!E$2:E$51, A3, 'Project Pipeline'!H$2:H$51, "<>Approved") -> 11 | D3: 40 | E3: 20 | F3: =E3/D3 -> 0.5
A4: Sarah Khan | B4: Illustrator | C4: =COUNTIFS('Project Pipeline'!E$2:E$51, A4, 'Project Pipeline'!H$2:H$51, "<>Approved") -> 11 | D4: 40 | E4: 30 | F4: =E4/D4 -> 0.75
A5: Zain Ahmed | B5: Junior Designer | C5: =COUNTIFS('Project Pipeline'!E$2:E$51, A5, 'Project Pipeline'!H$2:H$51, "<>Approved") -> 9 | D5: 40 | E5: 40 | F5: =E5/D5 -> 1

Sheet Financial Tracking
A1: Project ID | B1: Project Budget | C1: Amount Invoiced | D1: Amount Paid | E1: Outstanding Balance | F1: Invoice Status
A2: DS-PRJ-001 | B2: 1600 | C2: 1600 | D2: 800 | E2: =B2-D2 -> 800 | F2: Partially Paid
A3: DS-PRJ-002 | B3: 1700 | C3: 1700 | D3: 850 | E3: =B3-D3 -> 850 | F3: Partially Paid
A4: DS-PRJ-003 | B4: 1800 | C4: 1800 | D4: 1800 | E4: =B4-D4 -> 0 | F4: Paid
A5: DS-PRJ-004 | B5: 1900 | C5: 1900 | D5: 950 | E5: =B5-D5 -> 950 | F5: Partially Paid
A6: DS-PRJ-005 | B6: 2000 | C6: 2000 | D6: 0 | E6: =B6-D6 -> 2000 | F6: Unsent
A7: DS-PRJ-006 | B7: 2100 | C7: 2100 | D7: 2100 | E7: =B7-D7 -> 0 | F7: Paid
A8: DS-PRJ-007 | B8: 2200 | C8: 2200 | D8: 1100 | E8: =B8-D8 -> 1100 | F8: Partially Paid
A9: DS-PRJ-008 | B9: 2300 | C9: 2300 | D9: 1150 | E9: =B9-D9 -> 1150 | F9: Partially Paid
A10: DS-PRJ-009 | B10: 2400 | C10: 2400 | D10: 2400 | E10: =B10-D10 -> 0 | F10: Paid
A11: DS-PRJ-010 | B11: 2500 | C11: 2500 | D11: 0 | E11: =B11-D11 -> 2500 | F11: Unsent
A12: DS-PRJ-011 | B12: 2600 | C12: 2600 | D12: 1300 | E12: =B12-D12 -> 1300 | F12: Partially Paid
A13: DS-PRJ-012 | B13: 2700 | C13: 2700 | D13: 2700 | E13: =B13-D13 -> 0 | F13: Paid
... A51: DS-PRJ-050 | B51: 6500 | C51: 6500 | D51: 0 | E51: =B51-D51 -> 6500 | F51: Unsent
A52: Total | B52: =SUM(B2:B51) -> 202500 | C52: =SUM(C2:C51) -> 202500 | D52: =SUM(D2:D51) -> 119150 | E52: =SUM(E2:E51) -> 83350
